Workbook

Sheet Revise esta hoja
B2: Ejercicio 2
B3: Resumen de 5 números
C4: =moras[[#Headers],[SALARIO]] -> SALARIO | D4: =moras[[#Headers],[EDAD]] -> EDAD
B5: Mínimo | C5: =MIN('Y esta otra'!C2:C5001) -> 0 | D5: =MIN('Y esta otra'!I2:I5001) -> 14
B6: Máximo | C6: =MAX('Y esta otra'!C2:C5001) -> 16858742 | D6: =MAX('Y esta otra'!I2:I5001) -> 99
B7: Primer Cuartil | C7: =_xlfn.PERCENTILE.INC('Revise esta hoja'!C4817:C5001, 0.25) -> #NUM! | D7: =_xlfn.PERCENTILE.INC('Y esta otra'!I2:I5001, 0.25) -> 31
B8: Mediana | C8: =MEDIAN('Y esta otra'!C2:C5001) -> 408100 | D8: =MEDIAN('Y esta otra'!I2:I5001) -> 40
B9: Tercer Cuartil | C9: =_xlfn.PERCENTILE.INC('Revise esta hoja'!C4819:C5003, 0.75) -> #NUM! | D9: =_xlfn.PERCENTILE.INC('Y esta otra'!I2:I5001, 0.75) -> 52
B10: Promedio | C10: =AVERAGE('Y esta otra'!C2:C5001) -> 657425.24 | D10: =AVERAGE('Y esta otra'!I2:I5001) -> 41.906344
B11: Para el siguiente ejercicio usamos
B12: Desviación estándar | C12: =_xlfn.STDEV.S(moras[SALARIO]) -> 811054.2 | D12: =moras[EDAD] -> 30

Sheet Y esta otra
A1: IDENTIFICACION | B1: SEXO | C1: SALARIO | D1: TIPO_ASEGURAMIENTO | E1: SECTOR | F1: INDICADOR_ACTIVO | G1: INDICADOR.EXTRANJERO | H1: INDICADOR_MOROSO | I1: EDAD | J1: Z-SCORE_SALARIO | K1: Z-SCORE_EDAD | L1: SALARIO-IMPUTADO | M1: TIPO_ASEGURADO_IMPUTADO | N1: EDAD_IMPUTADO
A2: 1 | B2: HOMBRE | D2: ASALARIADO | E2: SECTOR PUBLICO | F2: SI | G2: NO | H2: NO | I2: 42 | J2: =IF(1.96<ABS(C2-$S$23)/$S$24,"Atípico","No") -> No | K2: =IF(1.96<ABS((I2-$T$23)/$T$24),"Atípico", "No") -> No | L2: =IF(ISBLANK(C2),$S$23,C2) -> 657425.24 | M2: =IF(ISBLANK(D2),_xlfn.MODE.SNGL(moras[TIPO_ASEGURAMIENTO]),D2) -> ASALARIADO | N2: =IF(ISBLANK(moras[[#This Row],[EDAD]]),T23,moras[[#This Row],[EDAD]]) -> 42
A3: 2 | B3: HOMBRE | C3: 3315014 | D3: PENSIONADOS EN SU PROPIO SISTEMA | E3: SECTOR PUBLICO | F3: SI | G3: NO | H3: NO | I3: 77 | J3: =IF(1.96<ABS(C3-$S$23)/$S$24,"Atípico","No") -> Atípico | K3: =IF(1.96<ABS((I3-$T$23)/$T$24),"Atípico", "No") -> No | L3: =IF(ISBLANK(C3),$S$23,C3) -> 3315014 | M3: =IF(ISBLANK(D3),_xlfn.MODE.SNGL(moras[TIPO_ASEGURAMIENTO]),D3) -> PENSIONADOS EN SU PROPIO SISTEMA | N3: =IF(ISBLANK(moras[[#This Row],[EDAD]]),T24,moras[[#This Row],[EDAD]]) -> 77
A4: 3 | B4: MUJER | C4: 270486.01 | D4: ASALARIADO | E4: SECTOR PRIVADO | F4: SI | G4: NO | H4: NO | I4: 45 | J4: =IF(1.96<ABS(C4-$S$23)/$S$24,"Atípico","No") -> No | K4: =IF(1.96<ABS((I4-$T$23)/$T$24),"Atípico", "No") -> No | L4: =IF(ISBLANK(C4),$S$23,C4) -> 270486.01 | M4: =IF(ISBLANK(D4),_xlfn.MODE.SNGL(moras[TIPO_ASEGURAMIENTO]),D4) -> ASALARIADO | N4: =IF(ISBLANK(moras[[#This Row],[EDAD]]),T25,moras[[#This Row],[EDAD]]) -> 45
A5: 4 | B5: MUJER | C5: =MIN('Y esta otra'!C2) -> 0 | D5: ASALARIADO | E5: SECTOR PRIVADO | F5: SI | G5: NO | H5: NO | I5: 49 | J5: =IF(1.96<ABS(C5-$S$23)/$S$24,"Atípico","No") -> No | K5: =IF(1.96<ABS((I5-$T$23)/$T$24),"Atípico", "No") -> No | L5: =IF(ISBLANK(C5),$S$23,C5) -> 0 | M5: =IF(ISBLANK(D5),_xlfn.MODE.SNGL(moras[TIPO_ASEGURAMIENTO]),D5) -> ASALARIADO | N5: =IF(ISBLANK(moras[[#This Row],[EDAD]]),T26,moras[[#This Row],[EDAD]]) -> 49
A6: 5 | B6: MUJER | C6: 210000 | D6: ASALARIADO | E6: SECTOR PRIVADO | F6: SI | G6: NO | H6: NO | I6: 42 | J6: =IF(1.96<ABS(C6-$S$23)/$S$24,"Atípico","No") -> No | K6: =IF(1.96<ABS((I6-$T$23)/$T$24),"Atípico", "No") -> No | L6: =IF(ISBLANK(C6),$S$23,C6) -> 210000 | M6: =IF(ISBLANK(D6),_xlfn.MODE.SNGL(moras[TIPO_ASEGURAMIENTO]),D6) -> ASALARIADO | N6: =IF(ISBLANK(moras[[#This Row],[EDAD]]),T27,moras[[#This Row],[EDAD]]) -> 42 | T6: =INDEX(moras[TIPO_ASEGURAMIENTO],MATCH(MAX(IF(moras[TIPO_ASEGURAMIENTO]<>"",COUNTIF(moras[TIPO_ASEGURAMIENTO],moras[TIPO_ASEGURAMIENTO]))),IF(moras[TIPO_ASEGURAMIENTO]<>"",COUNTIF(moras[TIPO_ASEGURAMIENTO],moras[TIPO_ASEGURAMIENTO])),0)) -> #N/A
A7: 6 | B7: HOMBRE | C7: 397150 | D7: ASALARIADO | E7: SECTOR PRIVADO | F7: SI | G7: NO | H7: NO | I7: 44 | J7: =IF(1.96<ABS(C7-$S$23)/$S$24,"Atípico","No") -> No | K7: =IF(1.96<ABS((I7-$T$23)/$T$24),"Atípico", "No") -> No | L7: =IF(ISBLANK(C7),$S$23,C7) -> 397150 | M7: =IF(ISBLANK(D7),_xlfn.MODE.SNGL(moras[TIPO_ASEGURAMIENTO]),D7) -> ASALARIADO | N7: =IF(ISBLANK(moras[[#This Row],[EDAD]]),T28,moras[[#This Row],[EDAD]]) -> 44 | T7: =INDEX(moras[TIPO_ASEGURAMIENTO],MATCH(MAX(IF(moras[TIPO_ASEGURAMIENTO]<>"",COUNTIF(moras[TIPO_ASEGURAMIENTO],moras[TIPO_ASEGURAMIENTO]))),IF(moras[TIPO_ASEGURAMIENTO]<>"",COUNTIF(moras[TIPO_ASEGURAMIENTO],moras[TIPO_ASEGURAMIENTO])),0)) -> #N/A
A8: 7 | B8: HOMBRE | C8: 854712 | D8: ASALARIADO | E8: SECTOR PRIVADO | F8: SI | G8: NO | H8: NO | I8: 38 | J8: =IF(1.96<ABS(C8-$S$23)/$S$24,"Atípico","No") -> No | K8: =IF(1.96<ABS((I8-$T$23)/$T$24),"Atípico", "No") -> No | L8: =IF(ISBLANK(C8),$S$23,C8) -> 854712 | M8: =IF(ISBLANK(D8),_xlfn.MODE.SNGL(moras[TIPO_ASEGURAMIENTO]),D8) -> ASALARIADO | N8: =IF(ISBLANK(moras[[#This Row],[EDAD]]),T29,moras[[#This Row],[EDAD]]) -> 38 | R8: =INDEX(moras[TIPO_ASEGURAMIENTO],MATCH(MAX(IF(moras[TIPO_ASEGURAMIENTO]<>"",COUNTIF(moras[TIPO_ASEGURAMIENTO],moras[TIPO_ASEGURAMIENTO]))),IF(moras[TIPO_ASEGURAMIENTO]<>"",COUNTIF(moras[TIPO_ASEGURAMIENTO],moras[TIPO_ASEGURAMIENTO])),0)) -> #N/A
A9: 8 | B9: HOMBRE | C9: 401000 | D9: ASALARIADO | E9: SECTOR PRIVADO | F9: SI | G9: SI | H9: SI | I9: 36 | J9: =IF(1.96<ABS(C9-$S$23)/$S$24,"Atípico","No") -> No | K9: =IF(1.96<ABS((I9-$T$23)/$T$24),"Atípico", "No") -> No | L9: =IF(ISBLANK(C9),$S$23,C9) -> 401000 | M9: =IF(ISBLANK(D9),_xlfn.MODE.SNGL(moras[TIPO_ASEGURAMIENTO]),D9) -> ASALARIADO | N9: =IF(ISBLANK(moras[[#This Row],[EDAD]]),T30,moras[[#This Row],[EDAD]]) -> 36
A10: 9 | B10: MUJER | C10: 264703.96 | D10: ASALARIADO | E10: SECTOR PRIVADO | F10: SI | G10: NO | H10: NO | I10: 21 | J10: =IF(1.96<ABS(C10-$S$23)/$S$24,"Atípico","No") -> No | K10: =IF(1.96<ABS((I10-$T$23)/$T$24),"Atípico", "No") -> No | L10: =IF(ISBLANK(C10),$S$23,C10) -> 264703.96 | M10: =IF(ISBLANK(D10),_xlfn.MODE.SNGL(moras[TIPO_ASEGURAMIENTO]),D10) -> ASALARIADO | N10: =IF(ISBLANK(moras[[#This Row],[EDAD]]),T31,moras[[#This Row],[EDAD]]) -> 21
A11: 10 | B11: HOMBRE | C11: 4677126.8 | D11: ASALARIADO | E11: SECTOR PRIVADO | F11: SI | G11: NO | H11: NO | I11: 40 | J11: =IF(1.96<ABS(C11-$S$23)/$S$24,"Atípico","No") -> Atípico | K11: =IF(1.96<ABS((I11-$T$23)/$T$24),"Atípico", "No") -> No | L11: =IF(ISBLANK(C11),$S$23,C11) -> 4677126.8 | M11: =IF(ISBLANK(D11),_xlfn.MODE.SNGL(moras[TIPO_ASEGURAMIENTO]),D11) -> ASALARIADO | N11: =IF(ISBLANK(moras[[#This Row],[EDAD]]),T32,moras[[#This Row],[EDAD]]) -> 40
A12: 11 | B12: MUJER | C12: 1200000 | D12: ASALARIADO | E12: SECTOR PRIVADO | F12: SI | G12: NO | H12: NO | I12: 30 | J12: =IF(1.96<ABS(C12-$S$23)/$S$24,"Atípico","No") -> No | K12: =IF(1.96<ABS((I12-$T$23)/$T$24),"Atípico", "No") -> No | L12: =IF(ISBLANK(C12),$S$23,C12) -> 1200000 | M12: =IF(ISBLANK(D12),_xlfn.MODE.SNGL(moras[TIPO_ASEGURAMIENTO]),D12) -> ASALARIADO | N12: =IF(ISBLANK(moras[[#This Row],[EDAD]]),T33,moras[[#This Row],[EDAD]]) -> 30
A13: 12 | B13: MUJER | C13: 1030132 | D13: ASALARIADO | E13: SECTOR PUBLICO | F13: SI | G13: NO | H13: SI | I13: 58 | J13: =IF(1.96<ABS(C13-$S$23)/$S$24,"Atípico","No") -> No | K13: =IF(1.96<ABS((I13-$T$23)/$T$24),"Atípico", "No") -> No | L13: =IF(ISBLANK(C13),$S$23,C13) -> 1030132 | M13: =IF(ISBLANK(D13),_xlfn.MODE.SNGL(moras[TIPO_ASEGURAMIENTO]),D13) -> ASALARIADO | N13: =IF(ISBLANK(moras[[#This Row],[EDAD]]),T34,moras[[#This Row],[EDAD]]) -> 58 | T13: =INDEX(moras[TIPO_ASEGURAMIENTO],MATCH(MAX(IF(moras[TIPO_ASEGURAMIENTO]<>"",COUNTIF(moras[TIPO_ASEGURAMIENTO],moras[TIPO_ASEGURAMIENTO]))),IF(moras[TIPO_ASEGURAMIENTO]<>"",COUNTIF(moras[TIPO_ASEGURAMIENTO],moras[TIPO_ASEGURAMIENTO])),0)) -> #N/A
A14: 13 | B14: HOMBRE | C14: 731287.5 | D14: ASALARIADO | E14: SECTOR PUBLICO | F14: SI | G14: NO | H14: NO | I14: 40 | J14: =IF(1.96<ABS(C14-$S$23)/$S$24,"Atípico","No") -> No | K14: =IF(1.96<ABS((I14-$T$23)/$T$24),"Atípico", "No") -> No | L14: =IF(ISBLANK(C14),$S$23,C14) -> 731287.5 | M14: =IF(ISBLANK(D14),_xlfn.MODE.SNGL(moras[TIPO_ASEGURAMIENTO]),D14) -> ASALARIADO | N14: =IF(ISBLANK(moras[[#This Row],[EDAD]]),T35,moras[[#This Row],[EDAD]]) -> 40
A15: 14 | B15: HOMBRE | C15: 282305 | D15: ASEGURADO VOLUNTARIO | E15: SECTOR PRIVADO | F15: SI | G15: NO | H15: NO | I15: 51 | J15: =IF(1.96<ABS(C15-$S$23)/$S$24,"Atípico","No") -> No | K15: =IF(1.96<ABS((I15-$T$23)/$T$24),"Atípico", "No") -> No | L15: =IF(ISBLANK(C15),$S$23,C15) -> 282305 | M15: =IF(ISBLANK(D15),_xlfn.MODE.SNGL(moras[TIPO_ASEGURAMIENTO]),D15) -> ASEGURADO VOLUNTARIO | N15: =IF(ISBLANK(moras[[#This Row],[EDAD]]),T36,moras[[#This Row],[EDAD]]) -> 51 | P15: =MO -> #NAME?
A16: 15 | B16: MUJER | C16: 343390.86 | D16: TRABAJADOR INDEPENDIENTE | E16: SECTOR PRIVADO | F16: SI | G16: NO | H16: NO | I16: 59 | J16: =IF(1.96<ABS(C16-$S$23)/$S$24,"Atípico","No") -> No | K16: =IF(1.96<ABS((I16-$T$23)/$T$24),"Atípico", "No") -> No | L16: =IF(ISBLANK(C16),$S$23,C16) -> 343390.86 | M16: =IF(ISBLANK(D16),_xlfn.MODE.SNGL(moras[TIPO_ASEGURAMIENTO]),D16) -> TRABAJADOR INDEPENDIENTE | N16: =IF(ISBLANK(moras[[#This Row],[EDAD]]),T37,moras[[#This Row],[EDAD]]) -> 59
A17: 16 | B17: MUJER | C17: 1943489.5 | D17: ASALARIADO | E17: SECTOR PUBLICO | F17: SI | G17: NO | H17: NO | I17: 58 | J17: =IF(1.96<ABS(C17-$S$23)/$S$24,"Atípico","No") -> No | K17: =IF(1.96<ABS((I17-$T$23)/$T$24),"Atípico", "No") -> No | L17: =IF(ISBLANK(C17),$S$23,C17) -> 1943489.5 | M17: =IF(ISBLANK(D17),_xlfn.MODE.SNGL(moras[TIPO_ASEGURAMIENTO]),D17) -> ASALARIADO | N17: =IF(ISBLANK(moras[[#This Row],[EDAD]]),T38,moras[[#This Row],[EDAD]]) -> 58
A18: 17 | B18: MUJER | C18: 1108980 | D18: ASALARIADO | E18: SECTOR PUBLICO | F18: SI | G18: NO | H18: SI | I18: 36 | J18: =IF(1.96<ABS(C18-$S$23)/$S$24,"Atípico","No") -> No | K18: =IF(1.96<ABS((I18-$T$23)/$T$24),"Atípico", "No") -> No | L18: =IF(ISBLANK(C18),$S$23,C18) -> 1108980 | M18: =IF(ISBLANK(D18),_xlfn.MODE.SNGL(moras[TIPO_ASEGURAMIENTO]),D18) -> ASALARIADO | N18: =IF(ISBLANK(moras[[#This Row],[EDAD]]),T39,moras[[#This Row],[EDAD]]) -> 36
A19: 18 | B19: MUJER | C19: 133157 | D19: ASALARIADO | E19: SECTOR PRIVADO | F19: SI | G19: NO | H19: NO | I19: 39 | J19: =IF(1.96<ABS(C19-$S$23)/$S$24,"Atípico","No") -> No | K19: =IF(1.96<ABS((I19-$T$23)/$T$24),"Atípico", "No") -> No | L19: =IF(ISBLANK(C19),$S$23,C19) -> 133157 | M19: =IF(ISBLANK(D19),_xlfn.MODE.SNGL(moras[TIPO_ASEGURAMIENTO]),D19) -> ASALARIADO | N19: =IF(ISBLANK(moras[[#This Row],[EDAD]]),T40,moras[[#This Row],[EDAD]]) -> 39
A20: 19 | B20: HOMBRE | C20: 553939 | D20: ASALARIADO | E20: SECTOR PRIVADO | F20: SI | G20: NO | H20: NO | I20: 45 | J20: =IF(1.96<ABS(C20-$S$23)/$S$24,"Atípico","No") -> No | K20: =IF(1.96<ABS((I20-$T$23)/$T$24),"Atípico", "No") -> No | L20: =IF(ISBLANK(C20),$S$23,C20) -> 553939 | M20: =IF(ISBLANK(D20),_xlfn.MODE.SNGL(moras[TIPO_ASEGURAMIENTO]),D20) -> ASALARIADO | N20: =IF(ISBLANK(moras[[#This Row],[EDAD]]),T41,moras[[#This Row],[EDAD]]) -> 45
A21: 20 | B21: MUJER | C21: 309820 | D21: ASEGURADO VOLUNTARIO | E21: SECTOR PRIVADO | F21: SI | G21: SI | H21: SI | I21: 52 | J21: =IF(1.96<ABS(C21-$S$23)/$S$24,"Atípico","No") -> No | K21: =IF(1.96<ABS((I21-$T$23)/$T$24),"Atípico", "No") -> No | L21: =IF(ISBLANK(C21),$S$23,C21) -> 309820 | M21: =IF(ISBLANK(D21),_xlfn.MODE.SNGL(moras[TIPO_ASEGURAMIENTO]),D21) -> ASEGURADO VOLUNTARIO | N21: =IF(ISBLANK(moras[[#This Row],[EDAD]]),T42,moras[[#This Row],[EDAD]]) -> 52
A22: 21 | B22: MUJER | D22: ASALARIADO | E22: SECTOR PRIVADO | F22: SI | G22: SI | H22: NO | I22: 28 | J22: =IF(1.96<ABS(C22-$S$23)/$S$24,"Atípico","No") -> No | K22: =IF(1.96<ABS((I22-$T$23)/$T$24),"Atípico", "No") -> No | L22: =IF(ISBLANK(C22),$S$23,C22) -> 657425.24 | M22: =IF(ISBLANK(D22),_xlfn.MODE.SNGL(moras[TIPO_ASEGURAMIENTO]),D22) -> ASALARIADO | N22: =IF(ISBLANK(moras[[#This Row],[EDAD]]),T43,moras[[#This Row],[EDAD]]) -> 28 | S22: salario | T22: edad
A23: 22 | B23: HOMBRE | C23: 278030 | D23: CONVENIOS ESPECIALES DE TRABAJADORES INDEPENDIENTES | E23: SECTOR PRIVADO | F23: SI | G23: NO | H23: NO | I23: 59 | J23: =IF(1.96<ABS(C23-$S$23)/$S$24,"Atípico","No") -> No | K23: =IF(1.96<ABS((I23-$T$23)/$T$24),"Atípico", "No") -> No | L23: =IF(ISBLANK(C23),$S$23,C23) -> 278030 | M23: =IF(ISBLANK(D23),_xlfn.MODE.SNGL(moras[TIPO_ASEGURAMIENTO]),D23) -> CONVENIOS ESPECIALES DE TRABAJADORES INDEPENDIENTES | N23: =IF(ISBLANK(moras[[#This Row],[EDAD]]),T44,moras[[#This Row],[EDAD]]) -> 59 | R23: Promedio | S23: ='Revise esta hoja'!C10 -> 657425.24 | T23: ='Revise esta hoja'!D10 -> 41.906344
A24: 23 | B24: HOMBRE | C24: 2124814 | D24: ASALARIADO | E24: SECTOR PRIVADO | F24: SI | G24: NO | H24: NO | I24: 32 | J24: =IF(1.96<ABS(C24-$S$23)/$S$24,"Atípico","No") -> No | K24: =IF(1.96<ABS((I24-$T$23)/$T$24),"Atípico", "No") -> No | L24: =IF(ISBLANK(C24),$S$23,C24) -> 2124814 | M24: =IF(ISBLANK(D24),_xlfn.MODE.SNGL(moras[TIPO_ASEGURAMIENTO]),D24) -> ASALARIADO | N24: =IF(ISBLANK(moras[[#This Row],[EDAD]]),T45,moras[[#This Row],[EDAD]]) -> 32 | R24: desviacion | S24: ='Revise esta hoja'!C12 -> 811054.2 | T24: ='Revise esta hoja'!D12 -> 30
A25: 24 | B25: HOMBRE | C25: 191744.68 | D25: ASALARIADO | E25: SECTOR PRIVADO | F25: SI | G25: NO | H25: NO | I25: 18 | J25: =IF(1.96<ABS(C25-$S$23)/$S$24,"Atípico","No") -> No | K25: =IF(1.96<ABS((I25-$T$23)/$T$24),"Atípico", "No") -> No | L25: =IF(ISBLANK(C25),$S$23,C25) -> 191744.68 | M25: =IF(ISBLANK(D25),_xlfn.MODE.SNGL(moras[TIPO_ASEGURAMIENTO]),D25) -> ASALARIADO | N25: =IF(ISBLANK(moras[[#This Row],[EDAD]]),T46,moras[[#This Row],[EDAD]]) -> 18
A26: 25 | B26: MUJER | C26: 1117489 | D26: ASALARIADO | E26: SECTOR PUBLICO | F26: SI | G26: NO | H26: SI | I26: 36 | J26: =IF(1.96<ABS(C26-$S$23)/$S$24,"Atípico","No") -> No | K26: =IF(1.96<ABS((I26-$T$23)/$T$24),"Atípico", "No") -> No | L26: =IF(ISBLANK(C26),$S$23,C26) -> 1117489 | M26: =IF(ISBLANK(D26),_xlfn.MODE.SNGL(moras[TIPO_ASEGURAMIENTO]),D26) -> ASALARIADO | N26: =IF(ISBLANK(moras[[#This Row],[EDAD]]),T47,moras[[#This Row],[EDAD]]) -> 36 | Q26: Valores faltantes | R26: Cantidad | S26: Porcentaje | U26: Cantiddad de filas
A27: 26 | B27: HOMBRE | C27: 1451530 | D27: PENSIONADOS EN SU PROPIO SISTEMA | E27: SECTOR PUBLICO | F27: SI | G27: NO | H27: NO | I27: 62 | J27: =IF(1.96<ABS(C27-$S$23)/$S$24,"Atípico","No") -> No | K27: =IF(1.96<ABS((I27-$T$23)/$T$24),"Atípico", "No") -> No | L27: =IF(ISBLANK(C27),$S$23,C27) -> 1451530 | M27: =IF(ISBLANK(D27),_xlfn.MODE.SNGL(moras[TIPO_ASEGURAMIENTO]),D27) -> PENSIONADOS EN SU PROPIO SISTEMA | N27: =IF(ISBLANK(moras[[#This Row],[EDAD]]),T48,moras[[#This Row],[EDAD]]) -> 62 | Q27: =moras[[#Headers],[IDENTIFICACION]] -> IDENTIFICACION | R27: =COUNTBLANK(moras[[#Headers],[IDENTIFICACION]]) -> 0 | S27: =R27/$U$27 -> 0 | U27: =COUNT(moras[IDENTIFICACION]) -> 5000
A28: 27 | B28: HOMBRE | C28: 66700 | D28: ASALARIADO | E28: SECTOR PRIVADO | F28: SI | G28: NO | H28: NO | I28: 38 | J28: =IF(1.96<ABS(C28-$S$23)/$S$24,"Atípico","No") -> No | K28: =IF(1.96<ABS((I28-$T$23)/$T$24),"Atípico", "No") -> No | L28: =IF(ISBLANK(C28),$S$23,C28) -> 66700 | M28: =IF(ISBLANK(D28),_xlfn.MODE.SNGL(moras[TIPO_ASEGURAMIENTO]),D28) -> ASALARIADO | N28: =IF(ISBLANK(moras[[#This Row],[EDAD]]),T49,moras[[#This Row],[EDAD]]) -> 38 | Q28: =moras[[#Headers],[SEXO]] -> SEXO | R28: =COUNTBLANK(B2:B5001) -> 0 | S28: =R28/$U$27 -> 0
A29: 28 | B29: MUJER | C29: 73410 | D29: ASALARIADO | E29: SECTOR PRIVADO | F29: SI | G29: SI | H29: NO | I29: 22 | J29: =IF(1.96<ABS(C29-$S$23)/$S$24,"Atípico","No") -> No | K29: =IF(1.96<ABS((I29-$T$23)/$T$24),"Atípico", "No") -> No | L29: =IF(ISBLANK(C29),$S$23,C29) -> 73410 | M29: =IF(ISBLANK(D29),_xlfn.MODE.SNGL(moras[TIPO_ASEGURAMIENTO]),D29) -> ASALARIADO | N29: =IF(ISBLANK(moras[[#This Row],[EDAD]]),T50,moras[[#This Row],[EDAD]]) -> 22 | Q29: =moras[[#Headers],[SALARIO]] -> SALARIO | R29: =COUNTBLANK(moras[SALARIO]) -> 3 | S29: =R29/$U$27 -> 0.0006
A30: 29 | B30: HOMBRE | C30: 815355.66 | D30: ASALARIADO | E30: SECTOR PUBLICO | F30: SI | G30: NO | H30: NO | I30: 42 | J30: =IF(1.96<ABS(C30-$S$23)/$S$24,"Atípico","No") -> No | K30: =IF(1.96<ABS((I30-$T$23)/$T$24),"Atípico", "No") -> No | L30: =IF(ISBLANK(C30),$S$23,C30) -> 815355.66 | M30: =IF(ISBLANK(D30),_xlfn.MODE.SNGL(moras[TIPO_ASEGURAMIENTO]),D30) -> ASALARIADO | N30: =IF(ISBLANK(moras[[#This Row],[EDAD]]),T51,moras[[#This Row],[EDAD]]) -> 42 | Q30: =moras[[#Headers],[TIPO_ASEGURAMIENTO]] -> TIPO_ASEGURAMIENTO | R30: =COUNTBLANK(moras[TIPO_ASEGURAMIENTO]) -> 2 | S30: =R30/$U$27 -> 0.0004
A31: 30 | B31: HOMBRE | C31: 398125 | D31: ASALARIADO | E31: SECTOR PRIVADO | F31: SI | G31: NO | H31: NO | I31: 38 | J31: =IF(1.96<ABS(C31-$S$23)/$S$24,"Atípico","No") -> No | K31: =IF(1.96<ABS((I31-$T$23)/$T$24),"Atípico", "No") -> No | L31: =IF(ISBLANK(C31),$S$23,C31) -> 398125 | M31: =IF(ISBLANK(D31),_xlfn.MODE.SNGL(moras[TIPO_ASEGURAMIENTO]),D31) -> ASALARIADO | N31: =IF(ISBLANK(moras[[#This Row],[EDAD]]),T52,moras[[#This Row],[EDAD]]) -> 38 | Q31: =moras[[#Headers],[SECTOR]] -> SECTOR | R31: =COUNTBLANK(moras[SECTOR]) -> 0 | S31: =R31/$U$27 -> 0 | W31: =INDEX(moras[TIPO_ASEGURAMIENTO],_xlfn.MODE.SNGL(IF(moras[TIPO_ASEGURAMIENTO]<>"", MATCH(moras[TIPO_ASEGURAMIENTO], moras[TIPO_ASEGURAMIENTO],0)))) -> #N/A
A32: 31 | B32: HOMBRE | C32: 606763.96 | D32: ASALARIADO | E32: SECTOR PRIVADO | F32: SI | G32: NO | H32: NO | I32: 39 | J32: =IF(1.96<ABS(C32-$S$23)/$S$24,"Atípico","No") -> No | K32: =IF(1.96<ABS((I32-$T$23)/$T$24),"Atípico", "No") -> No | L32: =IF(ISBLANK(C32),$S$23,C32) -> 606763.96 | M32: =IF(ISBLANK(D32),_xlfn.MODE.SNGL(moras[TIPO_ASEGURAMIENTO]),D32) -> ASALARIADO | N32: =IF(ISBLANK(moras[[#This Row],[EDAD]]),T53,moras[[#This Row],[EDAD]]) -> 39 | Q32: =moras[[#Headers],[INDICADOR_ACTIVO]] -> INDICADOR_ACTIVO | R32: =COUNTBLANK(moras[INDICADOR_ACTIVO]) -> 0 | S32: =R32/$U$27 -> 0
A33: 32 | B33: HOMBRE | C33: 360420 | D33: TRABAJADOR INDEPENDIENTE | E33: SECTOR PRIVADO | F33: SI | G33: NO | H33: SI | I33: 53 | J33: =IF(1.96<ABS(C33-$S$23)/$S$24,"Atípico","No") -> No | K33: =IF(1.96<ABS((I33-$T$23)/$T$24),"Atípico", "No") -> No | L33: =IF(ISBLANK(C33),$S$23,C33) -> 360420 | M33: =IF(ISBLANK(D33),_xlfn.MODE.SNGL(moras[TIPO_ASEGURAMIENTO]),D33) -> TRABAJADOR INDEPENDIENTE | N33: =IF(ISBLANK(moras[[#This Row],[EDAD]]),T54,moras[[#This Row],[EDAD]]) -> 53 | Q33: =moras[[#Headers],[INDICADOR.EXTRANJERO]] -> INDICADOR.EXTRANJERO | R33: =COUNTBLANK(moras[INDICADOR.EXTRANJERO]) -> 0 | S33: =R33/$U$27 -> 0
A34: 33 | B34: MUJER | C34: 297046 | D34: ASALARIADO | E34: SECTOR PRIVADO | F34: SI | G34: SI | H34: NO | I34: 41 | J34: =IF(1.96<ABS(C34-$S$23)/$S$24,"Atípico","No") -> No | K34: =IF(1.96<ABS((I34-$T$23)/$T$24),"Atípico", "No") -> No | L34: =IF(ISBLANK(C34),$S$23,C34) -> 297046 | M34: =IF(ISBLANK(D34),_xlfn.MODE.SNGL(moras[TIPO_ASEGURAMIENTO]),D34) -> ASALARIADO | N34: =IF(ISBLANK(moras[[#This Row],[EDAD]]),T55,moras[[#This Row],[EDAD]]) -> 41 | Q34: =moras[[#Headers],[INDICADOR_MOROSO]] -> INDICADOR_MOROSO | R34: =COUNTBLANK(moras[INDICADOR_MOROSO]) -> 0 | S34: =R34/$U$27 -> 0
A35: 34 | B35: HOMBRE | C35: 558030 | D35: ASALARIADO | E35: SECTOR PRIVADO | F35: SI | G35: NO | H35: NO | I35: 28 | J35: =IF(1.96<ABS(C35-$S$23)/$S$24,"Atípico","No") -> No | K35: =IF(1.96<ABS((I35-$T$23)/$T$24),"Atípico", "No") -> No | L35: =IF(ISBLANK(C35),$S$23,C35) -> 558030 | M35: =IF(ISBLANK(D35),_xlfn.MODE.SNGL(moras[TIPO_ASEGURAMIENTO]),D35) -> ASALARIADO | N35: =IF(ISBLANK(moras[[#This Row],[EDAD]]),T56,moras[[#This Row],[EDAD]]) -> 28 | Q35: =moras[[#Headers],[EDAD]] -> EDAD | R35: =COUNTBLANK(moras[EDAD]) -> 3 | S35: =R35/$U$27 -> 0.0006
A36: 35 | B36: HOMBRE | C36: 68309.03 | D36: ASALARIADO | E36: SECTOR PRIVADO | F36: SI | G36: NO | H36: NO | I36: 43 | J36: =IF(1.96<ABS(C36-$S$23)/$S$24,"Atípico","No") -> No | K36: =IF(1.96<ABS((I36-$T$23)/$T$24),"Atípico", "No") -> No | L36: =IF(ISBLANK(C36),$S$23,C36) -> 68309.03 | M36: =IF(ISBLANK(D36),_xlfn.MODE.SNGL(moras[TIPO_ASEGURAMIENTO]),D36) -> ASALARIADO | N36: =IF(ISBLANK(moras[[#This Row],[EDAD]]),T57,moras[[#This Row],[EDAD]]) -> 43
A37: 36 | B37: HOMBRE | D37: ASALARIADO | E37: SECTOR PUBLICO | F37: SI | G37: NO | H37: NO | I37: 62 | J37: =IF(1.96<ABS(C37-$S$23)/$S$24,"Atípico","No") -> No | K37: =IF(1.96<ABS((I37-$T$23)/$T$24),"Atípico", "No") -> No | L37: =IF(ISBLANK(C37),$S$23,C37) -> 657425.24 | M37: =IF(ISBLANK(D37),_xlfn.MODE.SNGL(moras[TIPO_ASEGURAMIENTO]),D37) -> ASALARIADO | N37: =IF(ISBLANK(moras[[#This Row],[EDAD]]),T58,moras[[#This Row],[EDAD]]) -> 62 | Q37: =moras[[#Headers],[SALARIO-IMPUTADO]] -> SALARIO-IMPUTADO | R37: =COUNTBLANK(moras[SALARIO-IMPUTADO]) -> 0
A38: 37 | B38: HOMBRE | C38: 1552307.5 | D38: ASALARIADO | E38: SECTOR PRIVADO | F38: SI | G38: SI | H38: NO | I38: 41 | J38: =IF(1.96<ABS(C38-$S$23)/$S$24,"Atípico","No") -> No | K38: =IF(1.96<ABS((I38-$T$23)/$T$24),"Atípico", "No") -> No | L38: =IF(ISBLANK(C38),$S$23,C38) -> 1552307.5 | M38: =IF(ISBLANK(D38),_xlfn.MODE.SNGL(moras[TIPO_ASEGURAMIENTO]),D38) -> ASALARIADO | N38: =IF(ISBLANK(moras[[#This Row],[EDAD]]),T59,moras[[#This Row],[EDAD]]) -> 41 | Q38: =moras[[#Headers],[TIPO_ASEGURADO_IMPUTADO]] -> TIPO_ASEGURADO_IMPUTADO | R38: =COUNTBLANK(moras[TIPO_ASEGURADO_IMPUTADO]) -> 0
A39: 38 | B39: HOMBRE | C39: 1531575 | D39: ASEGURADO VOLUNTARIO | E39: SECTOR PRIVADO | F39: SI | G39: SI | H39: NO | I39: 66 | J39: =IF(1.96<ABS(C39-$S$23)/$S$24,"Atípico","No") -> No | K39: =IF(1.96<ABS((I39-$T$23)/$T$24),"Atípico", "No") -> No | L39: =IF(ISBLANK(C39),$S$23,C39) -> 1531575 | M39: =IF(ISBLANK(D39),_xlfn.MODE.SNGL(moras[TIPO_ASEGURAMIENTO]),D39) -> ASEGURADO VOLUNTARIO | N39: =IF(ISBLANK(moras[[#This Row],[EDAD]]),T60,moras[[#This Row],[EDAD]]) -> 66 | Q39: =moras[[#Headers],[EDAD_IMPUTADO]] -> EDAD_IMPUTADO | R39: =COUNTBLANK(moras[EDAD_IMPUTADO]) -> 0
A40: 39 | B40: HOMBRE | C40: 3220569.1 | D40: ASALARIADO | E40: SECTOR PRIVADO | F40: SI | G40: NO | H40: NO | I40: 48 | J40: =IF(1.96<ABS(C40-$S$23)/$S$24,"Atípico","No") -> Atípico | K40: =IF(1.96<ABS((I40-$T$23)/$T$24),"Atípico", "No") -> No | L40: =IF(ISBLANK(C40),$S$23,C40) -> 3220569.1 | M40: =IF(ISBLANK(D40),_xlfn.MODE.SNGL(moras[TIPO_ASEGURAMIENTO]),D40) -> ASALARIADO | N40: =IF(ISBLANK(moras[[#This Row],[EDAD]]),T61,moras[[#This Row],[EDAD]]) -> 48 | Q40: Ahora vamos a imputar esos datos
...

Sheet Hoja3
A3: SEXO | B3: Cuenta de SEXO
A4: HOMBRE | B4: 3012
A5: MUJER | B5: 1988

Sheet Hoja4
A3: TIPO_ASEGURADO_IMPUTADO | B3: Cuenta de TIPO_ASEGURADO_IMPUTADO
A4: ASALARIADO | B4: 3464
A5: ASEGURADO VOLUNTARIO | B5: 436
A6: CONVENIOS ESPECIALES DE ASEGURADOS VOLUNTARIOS | B6: 31
A7: CONVENIOS ESPECIALES DE TRABAJADORES INDEPENDIENTES | B7: 157
A8: PENSIONADOS EN SU PROPIO SISTEMA | B8: 212
A9: TRABAJADOR INDEPENDIENTE | B9: 700

Sheet Hoja5
A3: SECTOR | B3: Cuenta de SECTOR
A4: SECTOR PRIVADO | B4: 3906
A5: SECTOR PUBLICO | B5: 1094

Sheet Hoja6
A3: INDICADOR_ACTIVO | B3: Cuenta de INDICADOR_ACTIVO
A4: NO | B4: 34
A5: SI | B5: 4966

Sheet Hoja7
A3: INDICADOR.EXTRANJERO | B3: Cuenta de INDICADOR.EXTRANJERO
A4: NO | B4: 4397
A5: SI | B5: 603

Sheet Hoja8
A3: INDICADOR_MOROSO | B3: Cuenta de INDICADOR_MOROSO
A4: NO | B4: 4130
A5: SI | B5: 870

Sheet Hoja9
A3: Z-SCORE_SALARIO | B3: Cuenta de Z-SCORE_SALARIO
A4: Atípico | B4: 162
A5: No | B5: 4838
